<?xml version="1.0" ?>
<!-- =================================================================================== -->
<!-- |    This document was autogenerated by xacro from /home/lucasrebra/catkin_ws/src/mr_description/urdf/myrobot.xacro | -->
<!-- |    EDITING THIS FILE BY HAND IS NOT RECOMMENDED                                 | -->
<!-- =================================================================================== -->
<!--INCLUDES-->
<robot name="myrobot" xmlns:xacro="http://www.ros.org/wiki/xacro">
    <!--MACRO DE ARTICULACIONES-->
    <!--MACRO DE LOS BRAZOS DEL ROBOT BASADOS EN UN ARCHIVO MESH FILE CREADO CON AUTOCAD Y BLENDER-->
    <!--FIN DE INCLUDES-->
    <link name="base_link">
        
<inertial>
            <mass value="633" />
            <origin rpy="0 0 0" xyz="0 0 0" />
            <inertia ixx="0" ixy="0" ixz="0" iyy="0" iyz="0" izz="9.655" />
        </inertial>

        <collision>
            <origin rpy="0 0 0" xyz="0 0 0" />
            <geometry>
                <mesh filename="package://sainsmart_robot_description_pkg/meshes/baserobot.dae" scale="0.1 0.1 0.1" />
            </geometry>
        </collision>
        <visual>
            <origin rpy="0 0 0" xyz="0 0 0" />
            <geometry>
                <mesh filename="package://sainsmart_robot_description_pkg/meshes/baserobot.dae" scale="0.1 0.1 0.1" />
            </geometry>
            <material name="light_black" />
        </visual>
    </link>
    <joint name="base_link_link01" type="revolute">
        <axis xyz="0 0 1" />
        <limit effort="1000" lower="-3.14" upper="3.14" velocity="0.5" />
        <origin rpy="0 0 0" xyz="0 0 0" />
        <parent link="base_link" />
        <child link="link_01" />
    </joint>
    <transmission name="trans_base_link_link01">
        <type>transmission_interface/SimpleTransmission</type>
        <joint name="base_link_link01">
            <hardwareInterface>hardware_interface/EffortJointInterface</hardwareInterface>
        </joint>
        <actuator name="motor_base_link_link01">
            <hardwareInterface>hardware_interface/EffortJointInterface</hardwareInterface>
            <mechanicalReduction>1</mechanicalReduction>
        </actuator>
    </transmission>
    <transmission name="trans_base_link_link01">
        <type>transmission_interface/SimpleTransmission</type>
        <joint name="base_link_link01">
            <hardwareInterface>PositionJointInterface</hardwareInterface>
        </joint>
        <actuator name="motor_base_link_link01">
            <hardwareInterface>PositionJointInterface</hardwareInterface>
            <mechanicalReduction>1</mechanicalReduction>
        </actuator>
    </transmission>
    <link name="link_01">
        
<inertial>
            <mass value="157.633" />
            <origin rpy="0 0 0" xyz="0 0 6" />
            <inertia ixx="13.235" ixy="0" ixz="0" iyy="13.235" iyz="0" izz="9.655" />
        </inertial>

        <collision>
            <origin rpy="0 0 0" xyz="0 0 6" />
            <geometry>
                <mesh filename="package://sainsmart_robot_description_pkg/meshes/pieza1.dae" scale="0.1 0.1 0.1" />
            </geometry>
        </collision>
        <visual>
            <origin rpy="0 0 0" xyz="0 0 6" />
            <geometry>
                <mesh filename="package://sainsmart_robot_description_pkg/meshes/pieza1.dae" scale="0.1 0.1 0.1" />
            </geometry>
            <material name="light_black" />
        </visual>
    </link>
    <joint name="base_link01__link02" type="revolute">
        <axis xyz="0 1 0" />
        <limit effort="1000" lower="-3.14" upper="3.14" velocity="0.5" />
        <origin rpy="0 1.31 0" xyz="2.9 0 11" />
        <parent link="link_01" />
        <child link="link_02" />
    </joint>
    <transmission name="trans_base_link01__link02">
        <type>transmission_interface/SimpleTransmission</type>
        <joint name="base_link01__link02">
            <hardwareInterface>hardware_interface/EffortJointInterface</hardwareInterface>
        </joint>
        <actuator name="motor_base_link01__link02">
            <hardwareInterface>hardware_interface/EffortJointInterface</hardwareInterface>
            <mechanicalReduction>1</mechanicalReduction>
        </actuator>
    </transmission>
    <transmission name="trans_base_link01_link02">
        <type>transmission_interface/SimpleTransmission</type>
        <joint name="base_link01__link02">
            <hardwareInterface>PositionJointInterface</hardwareInterface>
        </joint>
        <actuator name="motor_base_link01_link02">
            <hardwareInterface>PositionJointInterface</hardwareInterface>
            <mechanicalReduction>1</mechanicalReduction>
        </actuator>
    </transmission>
    <link name="link_02">
        
<inertial>
            <mass value="157.633" />
            <origin rpy="0 0 0" xyz="0 0 0" />
            <inertia ixx="13.235" ixy="0" ixz="0" iyy="13.235" iyz="0" izz="9.655" />
        </inertial>

        <collision>
            <origin rpy="0 0 0" xyz="0 0 0" />
            <geometry>
                <mesh filename="package://sainsmart_robot_description_pkg/meshes/pieza3.dae" scale="0.1 0.1 0.1" />
            </geometry>
        </collision>
        <visual>
            <origin rpy="0 0 0" xyz="0 0 0" />
            <geometry>
                <mesh filename="package://sainsmart_robot_description_pkg/meshes/pieza3.dae" scale="0.1 0.1 0.1" />
            </geometry>
            <material name="light_black" />
        </visual>
    </link>
    <joint name="base_link01__link05" type="revolute">
        <axis xyz="0 1 0" />
        <limit effort="1000" lower="-3.14" upper="3.14" velocity="0.5" />
        <origin rpy="0 -1.31 0" xyz="-10.6 -0.3 3" />
        <parent link="link_02" />
        <child link="link_05" />
    </joint>
    <transmission name="trans_base_link01__link05">
        <type>transmission_interface/SimpleTransmission</type>
        <joint name="base_link01__link05">
            <hardwareInterface>hardware_interface/EffortJointInterface</hardwareInterface>
        </joint>
        <actuator name="motor_base_link01__link05">
            <hardwareInterface>hardware_interface/EffortJointInterface</hardwareInterface>
            <mechanicalReduction>1</mechanicalReduction>
        </actuator>
    </transmission>
    <transmission name="trans_base_link01_link05">
        <type>transmission_interface/SimpleTransmission</type>
        <joint name="base_link01__link05">
            <hardwareInterface>PositionJointInterface</hardwareInterface>
        </joint>
        <actuator name="motor_base_link01_link05">
            <hardwareInterface>PositionJointInterface</hardwareInterface>
            <mechanicalReduction>1</mechanicalReduction>
        </actuator>
    </transmission>
    <link name="link_05">
        
<inertial>
            <mass value="157.633" />
            <origin rpy="0 0 0" xyz="0 0 0" />
            <inertia ixx="13.235" ixy="0" ixz="0" iyy="13.235" iyz="0" izz="9.655" />
        </inertial>

        <collision>
            <origin rpy="0 0 0" xyz="0 0 0" />
            <geometry>
                <mesh filename="package://sainsmart_robot_description_pkg/meshes/pieza6.dae" scale="0.1 0.1 0.1" />
            </geometry>
        </collision>
        <visual>
            <origin rpy="0 0 0" xyz="0 0 0" />
            <geometry>
                <mesh filename="package://sainsmart_robot_description_pkg/meshes/pieza6.dae" scale="0.1 0.1 0.1" />
            </geometry>
            <material name="light_black" />
        </visual>
    </link>
    <joint name="base_link05__link06" type="revolute">
        <axis xyz="1 0 0" />
        <limit effort="1000" lower="-3.14" upper="3.14" velocity="0.5" />
        <origin rpy="0 0 0" xyz="0 0 2.6" />
        <parent link="link_05" />
        <child link="link_06" />
    </joint>
    <transmission name="trans_base_link05__link06">
        <type>transmission_interface/SimpleTransmission</type>
        <joint name="base_link05__link06">
            <hardwareInterface>hardware_interface/EffortJointInterface</hardwareInterface>
        </joint>
        <actuator name="motor_base_link05__link06">
            <hardwareInterface>hardware_interface/EffortJointInterface</hardwareInterface>
            <mechanicalReduction>1</mechanicalReduction>
        </actuator>
    </transmission>
    <transmission name="trans_base_link05_link06">
        <type>transmission_interface/SimpleTransmission</type>
        <joint name="base_link05__link06">
            <hardwareInterface>PositionJointInterface</hardwareInterface>
        </joint>
        <actuator name="motor_base_link05_link06">
            <hardwareInterface>PositionJointInterface</hardwareInterface>
            <mechanicalReduction>1</mechanicalReduction>
        </actuator>
    </transmission>
    <link name="link_06">
        
<inertial>
            <mass value="157.633" />
            <origin rpy="0 0 3.14" xyz="0 0 0" />
            <inertia ixx="13.235" ixy="0" ixz="0" iyy="13.235" iyz="0" izz="9.655" />
        </inertial>

        <collision>
            <origin rpy="0 0 3.14" xyz="0 0 0" />
            <geometry>
                <mesh filename="package://sainsmart_robot_description_pkg/meshes/pieza6buena.dae" scale="0.1 0.1 0.1" />
            </geometry>
        </collision>
        <visual>
            <origin rpy="0 0 3.14" xyz="0 0 0" />
            <geometry>
                <mesh filename="package://sainsmart_robot_description_pkg/meshes/pieza6buena.dae" scale="0.1 0.1 0.1" />
            </geometry>
            <material name="light_black" />
        </visual>
    </link>
    <gazebo>
        <static>false</static>
        <plugin filename="libgazebo_ros_control.so" name="gazebo_ros_control">
            <robotNamespace>/myrobot</robotNamespace>
            <robotSimType>gazebo_ros_control/DefaultRobotHWSim</robotSimType>
            <legacyModeNS>true</legacyModeNS>
        </plugin>
    </gazebo>
    <transmission name="trans_base_link_link01">
        <type>transmission_interface/SimpleTransmission</type>
        <joint name="base_link_link01">
            <hardwareInterface>hardware_interface/EffortJointInterface</hardwareInterface>
        </joint>
        <actuator name="base_link_link01_motor">
            <hardwareInterface>hardware_interface/EffortJointInterface</hardwareInterface>
            <mechanicalReduction>1</mechanicalReduction>
        </actuator>
    </transmission>
    <transmission name="trans_base_link01__link02">
        <type>transmission_interface/SimpleTransmission</type>
        <joint name="base_link01__link02">
            <hardwareInterface>hardware_interface/EffortJointInterface</hardwareInterface>
        </joint>
        <actuator name="base_link01__link02_motor">
            <hardwareInterface>hardware_interface/EffortJointInterface</hardwareInterface>
            <mechanicalReduction>1</mechanicalReduction>
        </actuator>
    </transmission>
    <transmission name="trans_base_link01__link05">
        <type>transmission_interface/SimpleTransmission</type>
        <joint name="base_link01__link05">
            <hardwareInterface>hardware_interface/EffortJointInterface</hardwareInterface>
        </joint>
        <actuator name="base_link01__link05_motor">
            <hardwareInterface>hardware_interface/EffortJointInterface</hardwareInterface>
            <mechanicalReduction>1</mechanicalReduction>
        </actuator>
    </transmission>
    <transmission name="trans_base_link05__link06">
        <type>transmission_interface/SimpleTransmission</type>
        <joint name="base_link05__link06">
            <hardwareInterface>hardware_interface/EffortJointInterface</hardwareInterface>
        </joint>
        <actuator name="base_link05__link06_motor">
            <hardwareInterface>hardware_interface/EffortJointInterface</hardwareInterface>
            <mechanicalReduction>1</mechanicalReduction>
        </actuator>
    </transmission>
    <gazebo>
        <plugin name="gazebo_ros_control" filename="libgazebo_ros_control.so">
            <robotNamespace>/</robotNamespace>
        </plugin>
    </gazebo>
</robot>

<transmission name="trans_base_link_link01">
        <type>transmission_interface/SimpleTransmission</type>
        <joint name="base_link_link01">
            <hardwareInterface>hardware_interface/EffortJointInterface</hardwareInterface>
        </joint>
        <actuator name="motor_base_link_link01">
            <hardwareInterface>hardware_interface/EffortJointInterface</hardwareInterface>
            <mechanicalReduction>1</mechanicalReduction>
        </actuator>
    </transmission>
    <transmission name="trans_base_link_link01">
        <type>transmission_interface/SimpleTransmission</type>
        <joint name="base_link_link01">
            <hardwareInterface>PositionJointInterface</hardwareInterface>
        </joint>
        <actuator name="motor_base_link_link01">
            <hardwareInterface>PositionJointInterface</hardwareInterface>
            <mechanicalReduction>1</mechanicalReduction>
        </actuator>
    </transmission>
    <link name="link_01">
        <inertial>
            <mass value="157.633" />
            <origin rpy="0 0 0" xyz="0 0 6" />
            <inertia ixx="13.235" ixy="0" ixz="0" iyy="13.235" iyz="0" izz="9.655" />
        </inertial>
        <collision>
            <origin rpy="0 0 0" xyz="0 0 6" />
            <geometry>
                <mesh filename="package://sainsmart_robot_description_pkg/meshes/pieza1.dae" scale="0.1 0.1 0.1" />
            </geometry>
        </collision>
        <visual>
            <origin rpy="0 0 0" xyz="0 0 6" />
            <geometry>
                <mesh filename="package://sainsmart_robot_description_pkg/meshes/pieza1.dae" scale="0.1 0.1 0.1" />
            </geometry>
            <material name="light_black" />
        </visual>
    </link>
    <joint name="base_link01__link02" type="revolute">
        <axis xyz="0 1 0" />
        <limit effort="1000" lower="-3.14" upper="3.14" velocity="0.5" />
        <origin rpy="0 1.31 0" xyz="2.9 0 11" />
        <parent link="link_01" />
        <child link="link_02" />
    </joint>
    <transmission name="trans_base_link01__link02">
        <type>transmission_interface/SimpleTransmission</type>
        <joint name="base_link01__link02">
            <hardwareInterface>hardware_interface/EffortJointInterface</hardwareInterface>
        </joint>
        <actuator name="motor_base_link01__link02">
            <hardwareInterface>hardware_interface/EffortJointInterface</hardwareInterface>
            <mechanicalReduction>1</mechanicalReduction>
        </actuator>
    </transmission>
    <transmission name="trans_base_link01_link02">
        <type>transmission_interface/SimpleTransmission</type>
        <joint name="base_link01__link02">
            <hardwareInterface>PositionJointInterface</hardwareInterface>
        </joint>
        <actuator name="motor_base_link01_link02">
            <hardwareInterface>PositionJointInterface</hardwareInterface>
            <mechanicalReduction>1</mechanicalReduction>
        </actuator>
    </transmission>
    <link name="link_02">
        <inertial>
            <mass value="157.633" />
            <origin rpy="0 0 0" xyz="0 0 0" />
            <inertia ixx="13.235" ixy="0" ixz="0" iyy="13.235" iyz="0" izz="9.655" />
        </inertial>
        <collision>
            <origin rpy="0 0 0" xyz="0 0 0" />
            <geometry>
                <mesh filename="package://sainsmart_robot_description_pkg/meshes/pieza3.dae" scale="0.1 0.1 0.1" />
            </geometry>
        </collision>
        <visual>
            <origin rpy="0 0 0" xyz="0 0 0" />
            <geometry>
                <mesh filename="package://sainsmart_robot_description_pkg/meshes/pieza3.dae" scale="0.1 0.1 0.1" />
            </geometry>
            <material name="light_black" />
        </visual>
    </link>
    <joint name="base_link01__link05" type="revolute">
        <axis xyz="0 1 0" />
        <limit effort="1000" lower="-3.14" upper="3.14" velocity="0.5" />
        <origin rpy="0 -1.31 0" xyz="-10.6 -0.3 3" />
        <parent link="link_02" />
        <child link="link_05" />
    </joint>
    <transmission name="trans_base_link01__link05">
        <type>transmission_interface/SimpleTransmission</type>
        <joint name="base_link01__link05">
            <hardwareInterface>hardware_interface/EffortJointInterface</hardwareInterface>
        </joint>
        <actuator name="motor_base_link01__link05">
            <hardwareInterface>hardware_interface/EffortJointInterface</hardwareInterface>
            <mechanicalReduction>1</mechanicalReduction>
        </actuator>
    </transmission>
    <transmission name="trans_base_link01_link05">
        <type>transmission_interface/SimpleTransmission</type>
        <joint name="base_link01__link05">
            <hardwareInterface>PositionJointInterface</hardwareInterface>
        </joint>
        <actuator name="motor_base_link01_link05">
            <hardwareInterface>PositionJointInterface</hardwareInterface>
            <mechanicalReduction>1</mechanicalReduction>
        </actuator>
    </transmission>
    <link name="link_05">
        <inertial>
            <mass value="157.633" />
            <origin rpy="0 0 0" xyz="0 0 0" />
            <inertia ixx="13.235" ixy="0" ixz="0" iyy="13.235" iyz="0" izz="9.655" />
        </inertial>
        <collision>
            <origin rpy="0 0 0" xyz="0 0 0" />
            <geometry>
                <mesh filename="package://sainsmart_robot_description_pkg/meshes/pieza6.dae" scale="0.1 0.1 0.1" />
            </geometry>
        </collision>
        <visual>
            <origin rpy="0 0 0" xyz="0 0 0" />
            <geometry>
                <mesh filename="package://sainsmart_robot_description_pkg/meshes/pieza6.dae" scale="0.1 0.1 0.1" />
            </geometry>
            <material name="light_black" />
        </visual>
    </link>
    <joint name="base_link05__link06" type="revolute">
        <axis xyz="1 0 0" />
        <limit effort="1000" lower="-3.14" upper="3.14" velocity="0.5" />
        <origin rpy="0 0 0" xyz="0 0 2.6" />
        <parent link="link_05" />
        <child link="link_06" />
    </joint>
    <transmission name="trans_base_link05__link06">
        <type>transmission_interface/SimpleTransmission</type>
        <joint name="base_link05__link06">
            <hardwareInterface>hardware_interface/EffortJointInterface</hardwareInterface>
        </joint>
        <actuator name="motor_base_link05__link06">
            <hardwareInterface>hardware_interface/EffortJointInterface</hardwareInterface>
            <mechanicalReduction>1</mechanicalReduction>
        </actuator>
    </transmission>
    <transmission name="trans_base_link05_link06">
        <type>transmission_interface/SimpleTransmission</type>
        <joint name="base_link05__link06">
            <hardwareInterface>PositionJointInterface</hardwareInterface>
        </joint>
        <actuator name="motor_base_link05_link06">
            <hardwareInterface>PositionJointInterface</hardwareInterface>
            <mechanicalReduction>1</mechanicalReduction>
        </actuator>
    </transmission>
    <link name="link_06">
        <inertial>
            <mass value="157.633" />
            <origin rpy="0 0 3.14" xyz="0 0 0" />
            <inertia ixx="13.235" ixy="0" ixz="0" iyy="13.235" iyz="0" izz="9.655" />
        </inertial>
        <collision>
            <origin rpy="0 0 3.14" xyz="0 0 0" />
            <geometry>
                <mesh filename="package://sainsmart_robot_description_pkg/meshes/pieza6buena.dae" scale="0.1 0.1 0.1" />
            </geometry>
        </collision>
        <visual>
            <origin rpy="0 0 3.14" xyz="0 0 0" />
            <geometry>
                <mesh filename="package://sainsmart_robot_description_pkg/meshes/pieza6buena.dae" scale="0.1 0.1 0.1" />
            </geometry>
            <material name="light_black" />
        </visual>
    </link>
    <gazebo>
        <static>false</static>
        <plugin filename="libgazebo_ros_control.so" name="gazebo_ros_control">
            <robotNamespace>/myrobot</robotNamespace>
            <robotSimType>gazebo_ros_control/DefaultRobotHWSim</robotSimType>
            <legacyModeNS>true</legacyModeNS>
        </plugin>
    </gazebo>
    <transmission name="trans_base_link_link01">
        <type>transmission_interface/SimpleTransmission</type>
        <joint name="base_link_link01">
            <hardwareInterface>hardware_interface/EffortJointInterface</hardwareInterface>
        </joint>
        <actuator name="base_link_link01_motor">
            <hardwareInterface>hardware_interface/EffortJointInterface</hardwareInterface>
            <mechanicalReduction>1</mechanicalReduction>
        </actuator>
    </transmission>
    <transmission name="trans_base_link01__link02">
        <type>transmission_interface/SimpleTransmission</type>
        <joint name="base_link01__link02">
            <hardwareInterface>hardware_interface/EffortJointInterface</hardwareInterface>
        </joint>
        <actuator name="base_link01__link02_motor">
            <hardwareInterface>hardware_interface/EffortJointInterface</hardwareInterface>
            <mechanicalReduction>1</mechanicalReduction>
        </actuator>
    </transmission>
    <transmission name="trans_base_link01__link05">
        <type>transmission_interface/SimpleTransmission</type>
        <joint name="base_link01__link05">
            <hardwareInterface>hardware_interface/EffortJointInterface</hardwareInterface>
        </joint>
        <actuator name="base_link01__link05_motor">
            <hardwareInterface>hardware_interface/EffortJointInterface</hardwareInterface>
            <mechanicalReduction>1</mechanicalReduction>
        </actuator>
    </transmission>
    <transmission name="trans_base_link05__link06">
        <type>transmission_interface/SimpleTransmission</type>
        <joint name="base_link05__link06">
            <hardwareInterface>hardware_interface/EffortJointInterface</hardwareInterface>
        </joint>
        <actuator name="base_link05__link06_motor">
            <hardwareInterface>hardware_interface/EffortJointInterface</hardwareInterface>
            <mechanicalReduction>1</mechanicalReduction>
        </actuator>
    </transmission>
    <gazebo>
        <plugin name="gazebo_ros_control" filename="libgazebo_ros_control.so">
            <robotNamespace>/</robotNamespace>
        </plugin>
    </gazebo>
</robot>
